Workbook

Sheet Customers
A1: Customer ID | B1: Customer name | C1: Mobile no. | D1: POS (₹) | E1: Loan type | F1: Payment scheme | G1: Bullet: months of interest due | H1: Bullet: months bot should try to collect | I1: Monthly: months of interest unpaid | J1: Monthly: months to NPA | K1: Due amount (₹) | L1: Due since | M1: Risk tier | N1: Suggested channel | O1: Channel rationale | P1: Fallback channel | Q1: Treatment segment | R1: Suggested bot play | S1: Preferred language | T1: WhatsApp opt-in (Y/N) | U1: Preferred call window | V1: State | W1: City | X1: Branch | Y1: Loan account no. | Z1: Loan start date | AA1: Tenure (months) | AB1: Maturity date | AC1: Interest rate (% p.a.) | AD1: Monthly interest (₹) | AE1: Bot ask amount (₹) | AF1: Days past due | AG1: Last interest payment date | AH1: Days since last payment | AI1: eNACH registered | AJ1: Missed interest payments, last 6M | AK1: Broken promises-to-pay, last 3M | AL1: Bureau score | AM1: Off-us active loans (#) | AN1: Off-us delinquency (Y/N) | AO1: LTV (%) | AP1: Risk score (0-100) | AQ1: Last contact date | AR1: Last contact channel | AS1: Last contact outcome
A2: MFLC1000001 | B2: Shalini Joseph | C2: 9797186021 | D2: 83400 | E2: Gold loan | F2: Monthly interest | H2: =IF(F2="Bullet",MIN(G2,Assumptions!$B$6),"") | I2: 1 | J2: =IF(F2="Monthly interest",MAX(0,Assumptions!$B$5-I2),"") -> 2 | K2: =IF(F2="Bullet",G2*AD2,MAX(I2,1)*AD2) -> 1251 | L2: 46272 | M2: Low | N2: WhatsApp reminder | O2: Slipped regular payer: gentle digital nudge | P2: Voice bot | Q2: A - Regular monthly payer | R2: Gentle reminder + eNACH nudge | S2: Malayalam | T2: Y | U2: Afternoon (12-4pm) | V2: Kerala | W2: Kochi | X2: Kochi - Town Hall | Y2: GL9792667156 | Z2: 46180 | AA2: 24 | AB2: =EDATE(Z2,AA2) -> 46911 | AC2: 18 | AD2: =ROUND(D2*AC2/100/12,0) -> 1251 | AE2: =IF(F2="Bullet",H2*AD2,MIN(MAX(I2,1),Assumptions!$B$6)*AD2) -> 1251 | AF2: =IF(F2="Bullet",MAX(0,Assumptions!$B$4-AB2),MAX(0,Assumptions!$B$4-L2)) -> 26 | AG2: 46246 | AH2: =IF(AG2="","",Assumptions!$B$4-AG2) -> 52 | AI2: N | AJ2: 1 | AK2: 0 | AL2: 799 | AM2: 1 | AN2: N | AO2: 75 | AP2: 10 | AQ2: 46289 | AR2: WhatsApp reminder | AS2: Promised to pay
A3: MFLC1000002 | B3: Vasanthi Subramanian | C3: 7754456117 | D3: 252600 | E3: Gold loan | F3: Bullet | G3: 3 | H3: =IF(F3="Bullet",MIN(G3,Assumptions!$B$6),"") -> 2 | J3: =IF(F3="Monthly interest",MAX(0,Assumptions!$B$5-I3),"") | K3: =IF(F3="Bullet",G3*AD3,MAX(I3,1)*AD3) -> 7578 | L3: 46187 | M3: Medium | N3: Call center | O3: Early-stage delinquency: matched to risk and ticket size | P3: Field visit | Q3: E - Other early delinquent | R3: Reminder + payment link | S3: Tamil | T3: Y | U3: Afternoon (12-4pm) | V3: Tamil Nadu | W3: Tiruchirappalli | X3: Tiruchirappalli - MG Road | Y3: GL9546033474 | Z3: 46187 | AA3: 6 | AB3: =EDATE(Z3,AA3) -> 46370 | AC3: 12 | AD3: =ROUND(D3*AC3/100/12,0) -> 2526 | AE3: =IF(F3="Bullet",H3*AD3,MIN(MAX(I3,1),Assumptions!$B$6)*AD3) -> 5052 | AF3: =IF(F3="Bullet",MAX(0,Assumptions!$B$4-AB3),MAX(0,Assumptions!$B$4-L3)) -> 0 | AH3: =IF(AG3="","",Assumptions!$B$4-AG3) | AI3: NA | AK3: 1 | AL3: 618 | AM3: 0 | AN3: N | AO3: 65.1 | AP3: 36 | AQ3: 46293 | AR3: Voice bot | AS3: No response
A4: MFLC1000003 | B4: Seema Verma | C4: 6902921604 | D4: 68000 | E4: Gold loan | F4: Bullet | G4: 2 | H4: =IF(F4="Bullet",MIN(G4,Assumptions!$B$6),"") -> 2 | J4: =IF(F4="Monthly interest",MAX(0,Assumptions!$B$5-I4),"") | K4: =IF(F4="Bullet",G4*AD4,MAX(I4,1)*AD4) -> 2040 | L4: 46231 | M4: Low | N4: WhatsApp reminder | O4: Early-stage delinquency: matched to risk and ticket size | P4: Voice bot | Q4: E - Other early delinquent | R4: Reminder + payment link | S4: Hindi | T4: Y | U4: Evening (4-8pm) | V4: Rajasthan | W4: Kota | X4: Kota - Industrial Estate | Y4: GL0030869456 | Z4: 46231 | AA4: 12 | AB4: =EDATE(Z4,AA4) -> 46596 | AC4: 18 | AD4: =ROUND(D4*AC4/100/12,0) -> 1020 | AE4: =IF(F4="Bullet",H4*AD4,MIN(MAX(I4,1),Assumptions!$B$6)*AD4) -> 2040 | AF4: =IF(F4="Bullet",MAX(0,Assumptions!$B$4-AB4),MAX(0,Assumptions!$B$4-L4)) -> 0 | AH4: =IF(AG4="","",Assumptions!$B$4-AG4) | AI4: NA | AK4: 0 | AL4: 718 | AM4: 1 | AN4: N | AO4: 60 | AP4: 10 | AQ4: 46273 | AR4: Call center | AS4: Not reachable
A5: MFLC1000004 | B5: Pankaj Saxena | C5: 9381423040 | D5: 536700 | E5: Gold loan | F5: Monthly interest | H5: =IF(F5="Bullet",MIN(G5,Assumptions!$B$6),"") | I5: 1 | J5: =IF(F5="Monthly interest",MAX(0,Assumptions!$B$5-I5),"") -> 2 | K5: =IF(F5="Bullet",G5*AD5,MAX(I5,1)*AD5) -> 7156 | L5: 46278 | M5: Medium | N5: Voice bot | O5: No WhatsApp opt-in: routed to voice bot | P5: Call center | Q5: A - Regular monthly payer | R5: Gentle reminder + eNACH nudge | S5: Hindi | T5: N | U5: Evening (4-8pm) | V5: Uttar Pradesh | W5: Lucknow | X5: Lucknow - MG Road | Y5: GL9542959698 | Z5: 46155 | AA5: 24 | AB5: =EDATE(Z5,AA5) -> 46886 | AC5: 16 | AD5: =ROUND(D5*AC5/100/12,0) -> 7156 | AE5: =IF(F5="Bullet",H5*AD5,MIN(MAX(I5,1),Assumptions!$B$6)*AD5) -> 7156 | AF5: =IF(F5="Bullet",MAX(0,Assumptions!$B$4-AB5),MAX(0,Assumptions!$B$4-L5)) -> 20 | AG5: 46250 | AH5: =IF(AG5="","",Assumptions!$B$4-AG5) -> 48 | AI5: N | AJ5: 1 | AK5: 0 | AL5: 595 | AM5: 1 | AN5: N | AO5: 64.7 | AP5: 46 | AQ5: 46277 | AR5: Voice bot | AS5: No response
A6: MFLC1000005 | B6: Anitha Krishnan | C6: 7720933052 | D6: 109200 | E6: Gold loan | F6: Monthly interest | H6: =IF(F6="Bullet",MIN(G6,Assumptions!$B$6),"") | I6: 1 | J6: =IF(F6="Monthly interest",MAX(0,Assumptions!$B$5-I6),"") -> 2 | K6: =IF(F6="Bullet",G6*AD6,MAX(I6,1)*AD6) -> 2002 | L6: 46272 | M6: Low | N6: Voice bot | O6: Escalated: no response on whatsapp reminder | P6: Call center | Q6: A - Regular monthly payer | R6: Gentle reminder + eNACH nudge | S6: Tamil | T6: N | U6: Morning (9am-12pm) | V6: Tamil Nadu | W6: Madurai | X6: Madurai - Industrial Estate | Y6: GL2661127241 | Z6: 46180 | AA6: 12 | AB6: =EDATE(Z6,AA6) -> 46545 | AC6: 22 | AD6: =ROUND(D6*AC6/100/12,0) -> 2002 | AE6: =IF(F6="Bullet",H6*AD6,MIN(MAX(I6,1),Assumptions!$B$6)*AD6) -> 2002 | AF6: =IF(F6="Bullet",MAX(0,Assumptions!$B$4-AB6),MAX(0,Assumptions!$B$4-L6)) -> 26 | AG6: 46243 | AH6: =IF(AG6="","",Assumptions!$B$4-AG6) -> 55 | AI6: N | AJ6: 1 | AK6: 0 | AL6: 762 | AM6: 0 | AN6: N | AO6: 72 | AP6: 18 | AQ6: 46293 | AR6: WhatsApp reminder | AS6: No response
A7: MFLC1000006 | B7: Mani Raman | C7: 8986476026 | D7: 99900 | E7: Gold loan | F7: Monthly interest | H7: =IF(F7="Bullet",MIN(G7,Assumptions!$B$6),"") | I7: 1 | J7: =IF(F7="Monthly interest",MAX(0,Assumptions!$B$5-I7),"") -> 2 | K7: =IF(F7="Bullet",G7*AD7,MAX(I7,1)*AD7) -> 1998 | L7: 46289 | M7: Low | N7: WhatsApp reminder | O7: Slipped regular payer: gentle digital nudge | P7: Voice bot | Q7: A - Regular monthly payer | R7: Gentle reminder + eNACH nudge | S7: Tamil | T7: Y | U7: Evening (4-8pm) | V7: Tamil Nadu | W7: Madurai | X7: Madurai - Gandhi Nagar | Y7: GL4351950475 | Z7: 46015 | AA7: 12 | AB7: =EDATE(Z7,AA7) -> 46380 | AC7: 24 | AD7: =ROUND(D7*AC7/100/12,0) -> 1998 | AE7: =IF(F7="Bullet",H7*AD7,MIN(MAX(I7,1),Assumptions!$B$6)*AD7) -> 1998 | AF7: =IF(F7="Bullet",MAX(0,Assumptions!$B$4-AB7),MAX(0,Assumptions!$B$4-L7)) -> 9 | AG7: 46259 | AH7: =IF(AG7="","",Assumptions!$B$4-AG7) -> 39 | AI7: N | AJ7: 1 | AK7: 0 | AL7: 722 | AM7: 0 | AN7: N | AO7: 70.3 | AP7: 22 | AQ7: 46289 | AR7: Voice bot | AS7: No response
A8: MFLC1000007 | B8: Manoj Philip | C8: 7146416958 | D8: 127200 | E8: Gold loan | F8: Monthly interest | H8: =IF(F8="Bullet",MIN(G8,Assumptions!$B$6),"") | I8: 2 | J8: =IF(F8="Monthly interest",MAX(0,Assumptions!$B$5-I8),"") -> 1 | K8: =IF(F8="Bullet",G8*AD8,MAX(I8,1)*AD8) -> 3816 | L8: 46250 | M8: High | N8: Bot + call center | O8: Bouncing EII, high risk and high POS: bot first, call center for non-responders | P8: Field visit | Q8: D - Bouncing EII | R8: Reminder + part-payment negotiation, call center follow-up | S8: Malayalam | T8: Y | U8: Afternoon (12-4pm) | V8: Kerala | W8: Kochi | X8: Kochi - Station Road | Y8: GL4435519153 | Z8: 46069 | AA8: 24 | AB8: =EDATE(Z8,AA8) -> 46799 | AC8: 18 | AD8: =ROUND(D8*AC8/100/12,0) -> 1908 | AE8: =IF(F8="Bullet",H8*AD8,MIN(MAX(I8,1),Assumptions!$B$6)*AD8) -> 3816 | AF8: =IF(F8="Bullet",MAX(0,Assumptions!$B$4-AB8),MAX(0,Assumptions!$B$4-L8)) -> 48 | AG8: 46222 | AH8: =IF(AG8="","",Assumptions!$B$4-AG8) -> 76 | AI8: N | AJ8: 2 | AK8: 0 | AL8: 698 | AM8: 1 | AN8: N | AO8: 88 | AP8: 53 | AQ8: 46276 | AR8: Call center | AS8: Not reachable
A9: MFLC1000008 | B9: Biju Warrier | C9: 8709494509 | D9: 108900 | E9: Gold loan | F9: Monthly interest | H9: =IF(F9="Bullet",MIN(G9,Assumptions!$B$6),"") | I9: 1 | J9: =IF(F9="Monthly interest",MAX(0,Assumptions!$B$5-I9),"") -> 2 | K9: =IF(F9="Bullet",G9*AD9,MAX(I9,1)*AD9) -> 1271 | L9: 46298 | M9: Medium | N9: WhatsApp reminder | O9: Slipped regular payer: gentle digital nudge | P9: Voice bot | Q9: A - Regular monthly payer | R9: Gentle reminder + eNACH nudge | S9: Malayalam | T9: Y | U9: Morning (9am-12pm) | V9: Kerala | W9: Kottayam | X9: Kottayam - Station Road | Y9: GL8524472682 | Z9: 46025 | AA9: 24 | AB9: =EDATE(Z9,AA9) -> 46755 | AC9: 14 | AD9: =ROUND(D9*AC9/100/12,0) -> 1271 | AE9: =IF(F9="Bullet",H9*AD9,MIN(MAX(I9,1),Assumptions!$B$6)*AD9) -> 1271 | AF9: =IF(F9="Bullet",MAX(0,Assumptions!$B$4-AB9),MAX(0,Assumptions!$B$4-L9)) -> 0 | AG9: 46268 | AH9: =IF(AG9="","",Assumptions!$B$4-AG9) -> 30 | AI9: N | AJ9: 2 | AK9: 0 | AL9: 592 | AM9: 5 | AN9: N | AO9: 67.6 | AP9: 45 | AQ9: 46274 | AR9: WhatsApp reminder | AS9: Promised to pay
A10: MFLC1000009 | B10: Sunita Verma | C10: 7255797438 | D10: 52300 | E10: Gold loan | F10: Monthly interest | H10: =IF(F10="Bullet",MIN(G10,Assumptions!$B$6),"") | I10: 1 | J10: =IF(F10="Monthly interest",MAX(0,Assumptions!$B$5-I10),"") -> 2 | K10: =IF(F10="Bullet",G10*AD10,MAX(I10,1)*AD10) -> 785 | L10: 46289 | M10: Low | N10: Voice bot | O10: Escalated: not reachable on whatsapp reminder | P10: WhatsApp reminder | Q10: A - Regular monthly payer | R10: Gentle reminder + eNACH nudge | S10: Hindi | T10: Y | U10: Afternoon (12-4pm) | V10: Madhya Pradesh | W10: Bhopal | X10: Bhopal - Gandhi Nagar | Y10: GL0754123055 | Z10: 46046 | AA10: 12 | AB10: =EDATE(Z10,AA10) -> 46411 | AC10: 18 | AD10: =ROUND(D10*AC10/100/12,0) -> 785 | AE10: =IF(F10="Bullet",H10*AD10,MIN(MAX(I10,1),Assumptions!$B$6)*AD10) -> 785 | AF10: =IF(F10="Bullet",MAX(0,Assumptions!$B$4-AB10),MAX(0,Assumptions!$B$4-L10)) -> 9 | AG10: 46263 | AH10: =IF(AG10="","",Assumptions!$B$4-AG10) -> 35 | AI10: N | AJ10: 2 | AK10: 0 | AL10: 711 | AM10: 1 | AN10: N | AO10: 66.3 | AP10: 29 | AQ10: 46279 | AR10: WhatsApp reminder | AS10: Not reachable
A11: MFLC1000010 | B11: Dinesh Rajan | C11: 8788948999 | D11: 102300 | E11: Gold loan | F11: Monthly interest | H11: =IF(F11="Bullet",MIN(G11,Assumptions!$B$6),"") | I11: 1 | J11: =IF(F11="Monthly interest",MAX(0,Assumptions!$B$5-I11),"") -> 2 | K11: =IF(F11="Bullet",G11*AD11,MAX(I11,1)*AD11) -> 1876 | L11: 46283 | M11: Low | N11: WhatsApp reminder | O11: Slipped regular payer: gentle digital nudge | P11: Voice bot | Q11: A - Regular monthly payer | R11: Gentle reminder + eNACH nudge | S11: Tamil | T11: Y | U11: Morning (9am-12pm) | V11: Tamil Nadu | W11: Erode | X11: Erode - Temple Street | Y11: GL3949811627 | Z11: 46191 | AA11: 12 | AB11: =EDATE(Z11,AA11) -> 46556 | AC11: 22 | AD11: =ROUND(D11*AC11/100/12,0) -> 1876 | AE11: =IF(F11="Bullet",H11*AD11,MIN(MAX(I11,1),Assumptions!$B$6)*AD11) -> 1876 | AF11: =IF(F11="Bullet",MAX(0,Assumptions!$B$4-AB11),MAX(0,Assumptions!$B$4-L11)) -> 15 | AG11: 46256 | AH11: =IF(AG11="","",Assumptions!$B$4-AG11) -> 42 | AI11: N | AJ11: 1 | AK11: 0 | AL11: 744 | AM11: 0 | AN11: N | AO11: 66.8 | AP11: 21 | AQ11: 46294 | AR11: WhatsApp reminder | AS11: Promised to pay
A12: MFLC1000011 | B12: Vignesh Pandian | C12: 8309834299 | D12: 152700 | E12: Gold loan | F12: Monthly interest | H12: =IF(F12="Bullet",MIN(G12,Assumptions!$B$6),"") | I12: 1 | J12: =IF(F12="Monthly interest",MAX(0,Assumptions!$B$5-I12),"") -> 2 | K12: =IF(F12="Bullet",G12*AD12,MAX(I12,1)*AD12) -> 2036 | L12: 46278 | M12: Low | N12: Voice bot | O12: Escalated: no response on whatsapp reminder | P12: WhatsApp reminder | Q12: A - Regular monthly payer | R12: Gentle reminder + eNACH nudge | S12: Tamil | T12: Y | U12: Evening (4-8pm) | V12: Tamil Nadu | W12: Salem | X12: Salem - Civil Lines | Y12: GL1282382861 | Z12: 46186 | AA12: 12 | AB12: =EDATE(Z12,AA12) -> 46551 | AC12: 16 | AD12: =ROUND(D12*AC12/100/12,0) -> 2036 | AE12: =IF(F12="Bullet",H12*AD12,MIN(MAX(I12,1),Assumptions!$B$6)*AD12) -> 2036 | AF12: =IF(F12="Bullet",MAX(0,Assumptions!$B$4-AB12),MAX(0,Assumptions!$B$4-L12)) -> 20 | AG12: 46249 | AH12: =IF(AG12="","",Assumptions!$B$4-AG12) -> 49 | AI12: Y | AJ12: 2 | AK12: 0 | AL12: 771 | AM12: 2 | AN12: N | AO12: 69.5 | AP12: 21 | AQ12: 46296 | AR12: WhatsApp reminder | AS12: No response
A13: MFLC1000012 | B13: Binu Kumar | C13: 9082381936 | D13: 44200 | E13: Gold loan | F13: Monthly interest | H13: =IF(F13="Bullet",MIN(G13,Assumptions!$B$6),"") | I13: 2 | J13: =IF(F13="Monthly interest",MAX(0,Assumptions!$B$5-I13),"") -> 1 | K13: =IF(F13="Bullet",G13*AD13,MAX(I13,1)*AD13) -> 1768 | L13: 46243 | M13: Medium | N13: Voice bot | O13: Small ticket: bot-only, human cost not justified | P13: None - bot retry cadence | Q13: B - Small-ticket | R13: Standard reminder (no human follow-up) | S13: Malayalam | T13: Y | U13: Evening (4-8pm) | V13: Kerala | W13: Kannur | X13: Kannur - MG Road | Y13: GL4330979590 | Z13: 46090 | AA13: 12 | AB13: =EDATE(Z13,AA13) -> 46455 | AC13: 24 | AD13: =ROUND(D13*AC13/100/12,0) -> 884 | AE13: =IF(F13="Bullet",H13*AD13,MIN(MAX(I13,1),Assumptions!$B$6)*AD13) -> 1768 | AF13: =IF(F13="Bullet",MAX(0,Assumptions!$B$4-AB13),MAX(0,Assumptions!$B$4-L13)) -> 55 | AG13: 46216 | AH13: =IF(AG13="","",Assumptions!$B$4-AG13) -> 82 | AI13: Y | AJ13: 2 | AK13: 0 | AL13: NA | AM13: 0 | AN13: N | AO13: 74 | AP13: 45 | AS13: No prior contact
A14: MFLC1000013 | B14: Revathi Chandran | C14: 8872810772 | D14: 169000 | E14: Gold loan | F14: Monthly interest | H14: =IF(F14="Bullet",MIN(G14,Assumptions!$B$6),"") | I14: 2 | J14: =IF(F14="Monthly interest",MAX(0,Assumptions!$B$5-I14),"") -> 1 | K14: =IF(F14="Bullet",G14*AD14,MAX(I14,1)*AD14) -> 5634 | L14: 46262 | M14: High | N14: Bot + call center | O14: Bouncing EII, high risk and high POS: bot first, call center for non-responders | P14: Field visit | Q14: D - Bouncing EII | R14: Reminder + part-payment negotiation, call center follow-up | S14: Tamil | T14: N | U14: Afternoon (12-4pm) | V14: Tamil Nadu | W14: Madurai | X14: Madurai - Bus Stand | Y14: GL9606392082 | Z14: 46170 | AA14: 12 | AB14: =EDATE(Z14,AA14) -> 46535 | AC14: 20 | AD14: =ROUND(D14*AC14/100/12,0) -> 2817 | AE14: =IF(F14="Bullet",H14*AD14,MIN(MAX(I14,1),Assumptions!$B$6)*AD14) -> 5634 | AF14: =IF(F14="Bullet",MAX(0,Assumptions!$B$4-AB14),MAX(0,Assumptions!$B$4-L14)) -> 36 | AG14: 46235 | AH14: =IF(AG14="","",Assumptions!$B$4-AG14) -> 63 | AI14: Y | AJ14: 3 | AK14: 2 | AL14: 664 | AM14: 0 | AN14: N | AO14: 80.6 | AP14: 59 | AQ14: 46292 | AR14: WhatsApp reminder | AS14: Promised to pay
A15: MFLC1000014 | B15: Amit Yadav | C15: 8119480099 | D15: 137300 | E15: Gold loan | F15: Bullet | G15: 5 | H15: =IF(F15="Bullet",MIN(G15,Assumptions!$B$6),"") -> 2 | J15: =IF(F15="Monthly interest",MAX(0,Assumptions!$B$5-I15),"") | K15: =IF(F15="Bullet",G15*AD15,MAX(I15,1)*AD15) -> 8580 | L15: 46132 | M15: Medium | N15: Voice bot | O15: Accrued bullet: bot negotiates minimum amount due | P15: Call center | Q15: C - Accrued bullet | R15: Negotiate minimum amount due | S15: Hindi | T15: Y | U15: Morning (9am-12pm) | V15: Uttar Pradesh | W15: Noida | X15: Noida - Civil Lines | Y15: GL0246801055 | Z15: 46132 | AA15: 12 | AB15: =EDATE(Z15,AA15) -> 46497 | AC15: 15 | AD15: =ROUND(D15*AC15/100/12,0) -> 1716 | AE15: =IF(F15="Bullet",H15*AD15,MIN(MAX(I15,1),Assumptions!$B$6)*AD15) -> 3432 | AF15: =IF(F15="Bullet",MAX(0,Assumptions!$B$4-AB15),MAX(0,Assumptions!$B$4-L15)) -> 0 | AH15: =IF(AG15="","",Assumptions!$B$4-AG15) | AI15: NA | AK15: 1 | AL15: NA | AM15: 0 | AN15: N | AO15: 85.4 | AP15: 45 | AQ15: 46283 | AR15: Call center | AS15: No response
A16: MFLC1000015 | B16: Manoj Yadav | C16: 9796435955 | D16: 186400 | E16: Gold loan | F16: Bullet | G16: 2 | H16: =IF(F16="Bullet",MIN(G16,Assumptions!$B$6),"") -> 2 | J16: =IF(F16="Monthly interest",MAX(0,Assumptions!$B$5-I16),"") | K16: =IF(F16="Bullet",G16*AD16,MAX(I16,1)*AD16) -> 4660 | L16: 46229 | M16: Medium | N16: Voice bot | O16: Early-stage delinquency: matched to risk and ticket size | P16: Call center | Q16: E - Other early delinquent | R16: Reminder + payment link | S16: Hindi | T16: Y | U16: Evening (4-8pm) | V16: Delhi | W16: New Delhi | X16: New Delhi - MG Road | Y16: GL1478969052 | Z16: 46229 | AA16: 12 | AB16: =EDATE(Z16,AA16) -> 46594 | AC16: 15 | AD16: =ROUND(D16*AC16/100/12,0) -> 2330 | AE16: =IF(F16="Bullet",H16*AD16,MIN(MAX(I16,1),Assumptions!$B$6)*AD16) -> 4660 | AF16: =IF(F16="Bullet",MAX(0,Assumptions!$B$4-AB16),MAX(0,Assumptions!$B$4-L16)) -> 0 | AH16: =IF(AG16="","",Assumptions!$B$4-AG16) | AI16: NA | AK16: 0 | AL16: 645 | AM16: 2 | AN16: N | AO16: 66.2 | AP16: 31 | AQ16: 46274 | AR16: Field visit | AS16: Part payment made
A17: MFLC1000016 | B17: Bhavani Raju | C17: 9080104980 | D17: 149300 | E17: Gold loan | F17: Monthly interest | H17: =IF(F17="Bullet",MIN(G17,Assumptions!$B$6),"") | I17: 1 | J17: =IF(F17="Monthly interest",MAX(0,Assumptions!$B$5-I17),"") -> 2 | K17: =IF(F17="Bullet",G17*AD17,MAX(I17,1)*AD17) -> 1991 | L17: 46286 | M17: Low | N17: WhatsApp reminder | O17: Slipped regular payer: gentle digital nudge | P17: Voice bot | Q17: A - Regular monthly payer | R17: Gentle reminder + eNACH nudge | S17: Telugu | T17: Y | U17: Evening (4-8pm) | V17: Telangana | W17: Hyderabad | X17: Hyderabad - Nehru Nagar | Y17: GL6982532854 | Z17: 46133 | AA17: 12 | AB17: =EDATE(Z17,AA17) -> 46498 | AC17: 16 | AD17: =ROUND(D17*AC17/100/12,0) -> 1991 | AE17: =IF(F17="Bullet",H17*AD17,MIN(MAX(I17,1),Assumptions!$B$6)*AD17) -> 1991 | AF17: =IF(F17="Bullet",MAX(0,Assumptions!$B$4-AB17),MAX(0,Assumptions!$B$4-L17)) -> 12 | AG17: 46259 | AH17: =IF(AG17="","",Assumptions!$B$4-AG17) -> 39 | AI17: N | AJ17: 2 | AK17: 0 | AL17: 680 | AM17: 0 | AN17: N | AO17: 63 | AP17: 24 | AQ17: 46284 | AR17: Call center | AS17: Needs more time
A18: MFLC1000017 | B18: Divya Nair | C18: 7558224304 | D18: 93400 | E18: Gold loan | F18: Monthly interest | H18: =IF(F18="Bullet",MIN(G18,Assumptions!$B$6),"") | I18: 1 | J18: =IF(F18="Monthly interest",MAX(0,Assumptions!$B$5-I18),"") -> 2 | K18: =IF(F18="Bullet",G18*AD18,MAX(I18,1)*AD18) -> 1168 | L18: 46288 | M18: Low | N18: WhatsApp reminder | O18: Slipped regular payer: gentle digital nudge | P18: Voice bot | Q18: A - Regular monthly payer | R18: Gentle reminder + eNACH nudge | S18: Malayalam | T18: Y | U18: Afternoon (12-4pm) | V18: Kerala | W18: Kollam | X18: Kollam - Civil Lines | Y18: GL9539029181 | Z18: 46014 | AA18: 12 | AB18: =EDATE(Z18,AA18) -> 46379 | AC18: 15 | AD18: =ROUND(D18*AC18/100/12,0) -> 1168 | AE18: =IF(F18="Bullet",H18*AD18,MIN(MAX(I18,1),Assumptions!$B$6)*AD18) -> 1168 | AF18: =IF(F18="Bullet",MAX(0,Assumptions!$B$4-AB18),MAX(0,Assumptions!$B$4-L18)) -> 10 | AG18: 46260 | AH18: =IF(AG18="","",Assumptions!$B$4-AG18) -> 38 | AI18: N | AJ18: 1 | AK18: 0 | AL18: 731 | AM18: 1 | AN18: N | AO18: 62.5 | AP18: 17 | AS18: No prior contact
A19: MFLC1000018 | B19: Sravani Yadav | C19: 9068783467 | D19: 94700 | E19: Gold loan | F19: Bullet | G19: 4 | H19: =IF(F19="Bullet",MIN(G19,Assumptions!$B$6),"") -> 2 | J19: =IF(F19="Monthly interest",MAX(0,Assumptions!$B$5-I19),"") | K19: =IF(F19="Bullet",G19*AD19,MAX(I19,1)*AD19) -> 5684 | L19: 46175 | M19: Medium | N19: Voice bot | O19: Early-stage delinquency: matched to risk and ticket size | P19: Call center | Q19: E - Other early delinquent | R19: Reminder + payment link | S19: Telugu | T19: N | U19: Evening (4-8pm) | V19: Andhra Pradesh | W19: Tirupati | X19: Tirupati - Market Road | Y19: GL3712670973 | Z19: 46175 | AA19: 12 | AB19: =EDATE(Z19,AA19) -> 46540 | AC19: 18 | AD19: =ROUND(D19*AC19/100/12,0) -> 1421 | AE19: =IF(F19="Bullet",H19*AD19,MIN(MAX(I19,1),Assumptions!$B$6)*AD19) -> 2842 | AF19: =IF(F19="Bullet",MAX(0,Assumptions!$B$4-AB19),MAX(0,Assumptions!$B$4-L19)) -> 0 | AH19: =IF(AG19="","",Assumptions!$B$4-AG19) | AI19: NA | AK19: 1 | AL19: NA | AM19: 0 | AN19: N | AO19: 77.6 | AP19: 33 | AQ19: 46297 | AR19: WhatsApp reminder | AS19: No response
A20: MFLC1000019 | B20: Amit Tiwari | C20: 8559229999 | D20: 294600 | E20: Gold loan | F20: Bullet | G20: 3 | H20: =IF(F20="Bullet",MIN(G20,Assumptions!$B$6),"") -> 2 | J20: =IF(F20="Monthly interest",MAX(0,Assumptions!$B$5-I20),"") | K20: =IF(F20="Bullet",G20*AD20,MAX(I20,1)*AD20) -> 13257 | L20: 46194 | M20: High | N20: Bot + call center | O20: High risk: bot first, call center follows up | P20: Field visit | Q20: E - Other early delinquent | R20: Reminder + payment link | S20: Hindi | T20: N | U20: Morning (9am-12pm) | V20: Delhi | W20: Rohini | X20: Rohini - Gandhi Nagar | Y20: GL0918654665 | Z20: 46194 | AA20: 3 | AB20: =EDATE(Z20,AA20) -> 46286 | AC20: 18 | AD20: =ROUND(D20*AC20/100/12,0) -> 4419 | AE20: =IF(F20="Bullet",H20*AD20,MIN(MAX(I20,1),Assumptions!$B$6)*AD20) -> 8838 | AF20: =IF(F20="Bullet",MAX(0,Assumptions!$B$4-AB20),MAX(0,Assumptions!$B$4-L20)) -> 12 | AH20: =IF(AG20="","",Assumptions!$B$4-AG20) | AI20: NA | AK20: 2 | AL20: 695 | AM20: 1 | AN20: Y | AO20: 63.2 | AP20: 57 | AS20: No prior contact
A21: MFLC1000020 | B21: Manjula Kumar | C21: 9046649004 | D21: 96200 | E21: Gold loan | F21: Bullet | G21: 2 | H21: =IF(F21="Bullet",MIN(G21,Assumptions!$B$6),"") -> 2 | J21: =IF(F21="Monthly interest",MAX(0,Assumptions!$B$5-I21),"") | K21: =IF(F21="Bullet",G21*AD21,MAX(I21,1)*AD21) -> 2886 | L21: 46218 | M21: Low | N21: Voice bot | O21: No WhatsApp opt-in: routed to voice bot | P21: Call center | Q21: E - Other early delinquent | R21: Reminder + payment link | S21: Kannada | T21: N | U21: Afternoon (12-4pm) | V21: Karnataka | W21: Davanagere | X21: Davanagere - Temple Street | Y21: GL6476427482 | Z21: 46218 | AA21: 12 | AB21: =EDATE(Z21,AA21) -> 46583 | AC21: 18 | AD21: =ROUND(D21*AC21/100/12,0) -> 1443 | AE21: =IF(F21="Bullet",H21*AD21,MIN(MAX(I21,1),Assumptions!$B$6)*AD21) -> 2886 | AF21: =IF(F21="Bullet",MAX(0,Assumptions!$B$4-AB21),MAX(0,Assumptions!$B$4-L21)) -> 0 | AH21: =IF(AG21="","",Assumptions!$B$4-AG21) | AI21: NA | AK21: 0 | AL21: 771 | AM21: 1 | AN21: N | AO21: 71.9 | AP21: 8 | AQ21: 46297 | AR21: Voice bot | AS21: Promised to pay
A22: MFLC1000021 | B22: Geeta Kumar | C22: 9193917782 | D22: 18200 | E22: Gold loan | F22: Monthly interest | H22: =IF(F22="Bullet",MIN(G22,Assumptions!$B$6),"") | I22: 1 | J22: =IF(F22="Monthly interest",MAX(0,Assumptions!$B$5-I22),"") -> 2 | K22: =IF(F22="Bullet",G22*AD22,MAX(I22,1)*AD22) -> 303 | L22: 46274 | M22: Low | N22: WhatsApp reminder | O22: Small ticket: bot-only, human cost not justified | P22: Voice bot | Q22: B - Small-ticket | R22: Standard reminder (no human follow-up) | S22: Hindi | T22: Y | U22: Afternoon (12-4pm) | V22: Delhi | W22: New Delhi | X22: New Delhi - Town Hall | Y22: GL9470625750 | Z22: 46212 | AA22: 18 | AB22: =EDATE(Z22,AA22) -> 46761 | AC22: 20 | AD22: =ROUND(D22*AC22/100/12,0) -> 303 | AE22: =IF(F22="Bullet",H22*AD22,MIN(MAX(I22,1),Assumptions!$B$6)*AD22) -> 303 | AF22: =IF(F22="Bullet",MAX(0,Assumptions!$B$4-AB22),MAX(0,Assumptions!$B$4-L22)) -> 24 | AG22: 46248 | AH22: =IF(AG22="","",Assumptions!$B$4-AG22) -> 50 | AI22: N | AJ22: 1 | AK22: 1 | AL22: 806 | AM22: 1 | AN22: N | AO22: 57.9 | AP22: 20 | AQ22: 46282 | AR22: WhatsApp reminder | AS22: Needs more time
A23: MFLC1000022 | B23: Sreejith Joseph | C23: 9719256659 | D23: 166500 | E23: Gold loan | F23: Bullet | G23: 3 | H23: =IF(F23="Bullet",MIN(G23,Assumptions!$B$6),"") -> 2 | J23: =IF(F23="Monthly interest",MAX(0,Assumptions!$B$5-I23),"") | K23: =IF(F23="Bullet",G23*AD23,MAX(I23,1)*AD23) -> 5412 | L23: 46202 | M23: Medium | N23: Voice bot | O23: Early-stage delinquency: matched to risk and ticket size | P23: Call center | Q23: E - Other early delinquent | R23: Reminder + payment link | S23: Malayalam | T23: Y | U23: Evening (4-8pm) | V23: Kerala | W23: Kollam | X23: Kollam - Temple Street | Y23: GL6502495025 | Z23: 46202 | AA23: 6 | AB23: =EDATE(Z23,AA23) -> 46385 | AC23: 13 | AD23: =ROUND(D23*AC23/100/12,0) -> 1804 | AE23: =IF(F23="Bullet",H23*AD23,MIN(MAX(I23,1),Assumptions!$B$6)*AD23) -> 3608 | AF23: =IF(F23="Bullet",MAX(0,Assumptions!$B$4-AB23),MAX(0,Assumptions!$B$4-L23)) -> 0 | AH23: =IF(AG23="","",Assumptions!$B$4-AG23) | AI23: NA | AK23: 2 | AL23: 665 | AM23: 2 | AN23: N | AO23: 65.6 | AP23: 43 | AQ23: 46284 | AR23: Call center | AS23: Not reachable
A24: MFLC1000023 | B24: Basavaraj Gowda | C24: 9332822706 | D24: 427100 | E24: Gold loan | F24: Bullet | G24: 2 | H24: =IF(F24="Bullet",MIN(G24,Assumptions!$B$6),"") -> 2 | J24: =IF(F24="Monthly interest",MAX(0,Assumptions!$B$5-I24),"") | K24: =IF(F24="Bullet",G24*AD24,MAX(I24,1)*AD24) -> 12814 | L24: 46223 | M24: Low | N24: Voice bot | O24: No WhatsApp opt-in: routed to voice bot | P24: Call center | Q24: E - Other early delinquent | R24: Reminder + payment link | S24: Kannada | T24: N | U24: Morning (9am-12pm) | V24: Karnataka | W24: Belagavi | X24: Belagavi - Nehru Nagar | Y24: GL4783217487 | Z24: 46223 | AA24: 12 | AB24: =EDATE(Z24,AA24) -> 46588 | AC24: 18 | AD24: =ROUND(D24*AC24/100/12,0) -> 6407 | AE24: =IF(F24="Bullet",H24*AD24,MIN(MAX(I24,1),Assumptions!$B$6)*AD24) -> 12814 | AF24: =IF(F24="Bullet",MAX(0,Assumptions!$B$4-AB24),MAX(0,Assumptions!$B$4-L24)) -> 0 | AH24: =IF(AG24="","",Assumptions!$B$4-AG24) | AI24: NA | AK24: 0 | AL24: 790 | AM24: 1 | AN24: N | AO24: 57.5 | AP24: 9 | AQ24: 46282 | AR24: WhatsApp reminder | AS24: Part payment made
A25: MFLC1000024 | B25: Anitha Krishnan | C25: 8993723080 | D25: 60900 | E25: Gold loan | F25: Monthly interest | H25: =IF(F25="Bullet",MIN(G25,Assumptions!$B$6),"") | I25: 2 | J25: =IF(F25="Monthly interest",MAX(0,Assumptions!$B$5-I25),"") -> 1 | K25: =IF(F25="Bullet",G25*AD25,MAX(I25,1)*AD25) -> 1624 | L25: 46239 | M25: High | N25: Bot + call center | O25: Bouncing EII, high risk and high POS: bot first, call center for non-responders | P25: Field visit | Q25: D - Bouncing EII | R25: Reminder + part-payment negotiation, call center follow-up | S25: Tamil | T25: Y | U25: Evening (4-8pm) | V25: Tamil Nadu | W25: Erode | X25: Erode - Nehru Nagar | Y25: GL8810965675 | Z25: 46147 | AA25: 18 | AB25: =EDATE(Z25,AA25) -> 46696 | AC25: 16 | AD25: =ROUND(D25*AC25/100/12,0) -> 812 | AE25: =IF(F25="Bullet",H25*AD25,MIN(MAX(I25,1),Assumptions!$B$6)*AD25) -> 1624 | AF25: =IF(F25="Bullet",MAX(0,Assumptions!$B$4-AB25),MAX(0,Assumptions!$B$4-L25)) -> 59 | AG25: 46213 | AH25: =IF(AG25="","",Assumptions!$B$4-AG25) -> 85 | AI25: N | AJ25: 3 | AK25: 0 | AL25: 604 | AM25: 1 | AN25: N | AO25: 69 | AP25: 54 | AQ25: 46285 | AR25: Voice bot | AS25: No response
A26: MFLC1000025 | B26: Kiran Reddy | C26: 7951786467 | D26: 412600 | E26: Gold loan | F26: Monthly interest | H26: =IF(F26="Bullet",MIN(G26,Assumptions!$B$6),"") | I26: 2 | J26: =IF(F26="Monthly interest",MAX(0,Assumptions!$B$5-I26),"") -> 1 | K26: =IF(F26="Bullet",G26*AD26,MAX(I26,1)*AD26) -> 15128 | L26: 46259 | M26: Medium | N26: Call center | O26: Early-stage delinquency: matched to risk and ticket size | P26: Field visit | Q26: E - Other early delinquent | R26: Reminder + payment link | S26: Kannada | T26: Y | U26: Afternoon (12-4pm) | V26: Karnataka | W26: Mysuru | X26: Mysuru - Church Road | Y26: GL0058500675 | Z26: 46047 | AA26: 12 | AB26: =EDATE(Z26,AA26) -> 46412 | AC26: 22 | AD26: =ROUND(D26*AC26/100/12,0) -> 7564 | AE26: =IF(F26="Bullet",H26*AD26,MIN(MAX(I26,1),Assumptions!$B$6)*AD26) -> 15128 | AF26: =IF(F26="Bullet",MAX(0,Assumptions!$B$4-AB26),MAX(0,Assumptions!$B$4-L26)) -> 39 | AG26: 46229 | AH26: =IF(AG26="","",Assumptions!$B$4-AG26) -> 69 | AI26: Y | AJ26: 2 | AK26: 0 | AL26: 763 | AM26: 4 | AN26: N | AO26: 72.9 | AP26: 46 | AQ26: 46290 | AR26: Call center | AS26: Promised to pay
A27: MFLC1000026 | B27: Mathew Ibrahim | C27: 9341626753 | D27: 202100 | E27: Gold loan | F27: Monthly interest | H27: =IF(F27="Bullet",MIN(G27,Assumptions!$B$6),"") | I27: 2 | J27: =IF(F27="Monthly interest",MAX(0,Assumptions!$B$5-I27),"") -> 1 | K27: =IF(F27="Bullet",G27*AD27,MAX(I27,1)*AD27) -> 4716 | L27: 46262 | M27: Medium | N27: Call center | O27: Early-stage delinquency: matched to risk and ticket size | P27: Field visit | Q27: E - Other early delinquent | R27: Reminder + payment link | S27: Malayalam | T27: Y | U27: Evening (4-8pm) | V27: Kerala | W27: Kollam | X27: Kollam - Market Road | Y27: GL6462712855 | Z27: 46109 | AA27: 18 | AB27: =EDATE(Z27,AA27) -> 46658 | AC27: 14 | AD27: =ROUND(D27*AC27/100/12,0) -> 2358 | AE27: =IF(F27="Bullet",H27*AD27,MIN(MAX(I27,1),Assumptions!$B$6)*AD27) -> 4716 | AF27: =IF(F27="Bullet",MAX(0,Assumptions!$B$4-AB27),MAX(0,Assumptions!$B$4-L27)) -> 36 | AG27: 46236 | AH27: =IF(AG27="","",Assumptions!$B$4-AG27) -> 62 | AI27: N | AJ27: 2 | AK27: 0 | AL27: 794 | AM27: 2 | AN27: N | AO27: 74.1 | AP27: 33 | AQ27: 46283 | AR27: Voice bot | AS27: Part payment made
A28: MFLC1000027 | B28: Sunita Yadav | C28: 8719932145 | D28: 362800 | E28: Gold loan | F28: Monthly interest | H28: =IF(F28="Bullet",MIN(G28,Assumptions!$B$6),"") | I28: 1 | J28: =IF(F28="Monthly interest",MAX(0,Assumptions!$B$5-I28),"") -> 2 | K28: =IF(F28="Bullet",G28*AD28,MAX(I28,1)*AD28) -> 5442 | L28: 46287 | M28: Low | N28: Voice bot | O28: Escalated: not reachable on whatsapp reminder | P28: Call center | Q28: A - Regular monthly payer | R28: Gentle reminder + eNACH nudge | S28: English | T28: N | U28: Evening (4-8pm) | V28: Rajasthan | W28: Jaipur | X28: Jaipur - Church Road | Y28: GL1936564806 | Z28: 46225 | AA28: 18 | AB28: =EDATE(Z28,AA28) -> 46774 | AC28: 18 | AD28: =ROUND(D28*AC28/100/12,0) -> 5442 | AE28: =IF(F28="Bullet",H28*AD28,MIN(MAX(I28,1),Assumptions!$B$6)*AD28) -> 5442 | AF28: =IF(F28="Bullet",MAX(0,Assumptions!$B$4-AB28),MAX(0,Assumptions!$B$4-L28)) -> 11 | AG28: 46261 | AH28: =IF(AG28="","",Assumptions!$B$4-AG28) -> 37 | AI28: Y | AJ28: 1 | AK28: 0 | AL28: 653 | AM28: 0 | AN28: N | AO28: 53.4 | AP28: 24 | AQ28: 46288 | AR28: WhatsApp reminder | AS28: Not reachable
A29: MFLC1000028 | B29: Kumar Subramanian | C29: 9681029771 | D29: 72100 | E29: Gold loan | F29: Bullet | G29: 4 | H29: =IF(F29="Bullet",MIN(G29,Assumptions!$B$6),"") -> 2 | J29: =IF(F29="Monthly interest",MAX(0,Assumptions!$B$5-I29),"") | K29: =IF(F29="Bullet",G29*AD29,MAX(I29,1)*AD29) -> 3844 | L29: 46165 | M29: Medium | N29: Voice bot | O29: Early-stage delinquency: matched to risk and ticket size | P29: Call center | Q29: E - Other early delinquent | R29: Reminder + payment link | S29: Tamil | T29: Y | U29: Morning (9am-12pm) | V29: Tamil Nadu | W29: Tiruchirappalli | X29: Tiruchirappalli - Industrial Estate | Y29: GL9939265329 | Z29: 46165 | AA29: 6 | AB29: =EDATE(Z29,AA29) -> 46349 | AC29: 16 | AD29: =ROUND(D29*AC29/100/12,0) -> 961 | AE29: =IF(F29="Bullet",H29*AD29,MIN(MAX(I29,1),Assumptions!$B$6)*AD29) -> 1922 | AF29: =IF(F29="Bullet",MAX(0,Assumptions!$B$4-AB29),MAX(0,Assumptions!$B$4-L29)) -> 0 | AH29: =IF(AG29="","",Assumptions!$B$4-AG29) | AI29: NA | AK29: 2 | AL29: 725 | AM29: 1 | AN29: N | AO29: 83.1 | AP29: 43 | AQ29: 46281 | AR29: Call center | AS29: No response
A30: MFLC1000029 | B30: Deepak Saxena | C30: 9089541812 | D30: 85600 | E30: Gold loan | F30: Bullet | G30: 4 | H30: =IF(F30="Bullet",MIN(G30,Assumptions!$B$6),"") -> 2 | J30: =IF(F30="Monthly interest",MAX(0,Assumptions!$B$5-I30),"") | K30: =IF(F30="Bullet",G30*AD30,MAX(I30,1)*AD30) -> 3424 | L30: 46158 | M30: Medium | N30: Voice bot | O30: Early-stage delinquency: matched to risk and ticket size | P30: Call center | Q30: E - Other early delinquent | R30: Reminder + payment link | S30: Hindi | T30: Y | U30: Evening (4-8pm) | V30: Uttar Pradesh | W30: Agra | X30: Agra - Bus Stand | Y30: GL4552223620 | Z30: 46158 | AA30: 6 | AB30: =EDATE(Z30,AA30) -> 46342 | AC30: 12 | AD30: =ROUND(D30*AC30/100/12,0) -> 856 | AE30: =IF(F30="Bullet",H30*AD30,MIN(MAX(I30,1),Assumptions!$B$6)*AD30) -> 1712 | AF30: =IF(F30="Bullet",MAX(0,Assumptions!$B$4-AB30),MAX(0,Assumptions!$B$4-L30)) -> 0 | AH30: =IF(AG30="","",Assumptions!$B$4-AG30) | AI30: NA | AK30: 0 | AL30: 626 | AM30: 3 | AN30: N | AO30: 65.2 | AP30: 33 | AQ30: 46286 | AR30: WhatsApp reminder | AS30: No response
A31: MFLC1000030 | B31: Rajesh Singh | C31: 8553565681 | D31: 291400 | E31: Gold loan | F31: Bullet | G31: 1 | H31: =IF(F31="Bullet",MIN(G31,Assumptions!$B$6),"") -> 1 | J31: =IF(F31="Monthly interest",MAX(0,Assumptions!$B$5-I31),"") | K31: =IF(F31="Bullet",G31*AD31,MAX(I31,1)*AD31) -> 2914 | L31: 46266 | M31: Low | N31: Call center | O31: Escalated: customer refused/disputed, needs a human | P31: Field visit | Q31: E - Other early delinquent | R31: Reminder + payment link | S31: Hindi | T31: Y | U31: Morning (9am-12pm) | V31: Uttar Pradesh | W31: Agra | X31: Agra - Nehru Nagar | Y31: GL1478481668 | Z31: 46266 | AA31: 6 | AB31: =EDATE(Z31,AA31) -> 46447 | AC31: 12 | AD31: =ROUND(D31*AC31/100/12,0) -> 2914 | AE31: =IF(F31="Bullet",H31*AD31,MIN(MAX(I31,1),Assumptions!$B$6)*AD31) -> 2914 | AF31: =IF(F31="Bullet",MAX(0,Assumptions!$B$4-AB31),MAX(0,Assumptions!$B$4-L31)) -> 0 | AH31: =IF(AG31="","",Assumptions!$B$4-AG31) | AI31: NA | AK31: 0 | AL31: 711 | AM31: 0 | AN31: N | AO31: 61.1 | AP31: 13 | AQ31: 46277 | AR31: WhatsApp reminder | AS31: Refused / disputed
A32: MFLC1000031 | B32: Manjunath Swamy | C32: 8361072923 | D32: 440600 | E32: Gold loan | F32: Bullet | G32: 3 | H32: =IF(F32="Bullet",MIN(G32,Assumptions!$B$6),"") -> 2 | J32: =IF(F32="Monthly interest",MAX(0,Assumptions!$B$5-I32),"") | K32: =IF(F32="Bullet",G32*AD32,MAX(I32,1)*AD32) -> 17625 | L32: 46206 | M32: Medium | N32: Call center | O32: Early-stage delinquency: matched to risk and ticket size | P32: Field visit | Q32: E - Other early delinquent | R32: Reminder + payment link | S32: English | T32: Y | U32: Evening (4-8pm) | V32: Karnataka | W32: Mangaluru | X32: Mangaluru - Market Road | Y32: GL7322714338 | Z32: 46206 | AA32: 3 | AB32: =EDATE(Z32,AA32) -> 46298 | AC32: 16 | AD32: =ROUND(D32*AC32/100/12,0) -> 5875 | AE32: =IF(F32="Bullet",H32*AD32,MIN(MAX(I32,1),Assumptions!$B$6)*AD32) -> 11750 | AF32: =IF(F32="Bullet",MAX(0,Assumptions!$B$4-AB32),MAX(0,Assumptions!$B$4-L32)) -> 0 | AH32: =IF(AG32="","",Assumptions!$B$4-AG32) | AI32: NA | AK32: 1 | AL32: 702 | AM32: 2 | AN32: N | AO32: 69.2 | AP32: 34 | AQ32: 46291 | AR32: Call center | AS32: No response
A33: MFLC1000032 | B33: Vidya Kumar | C33: 7982704459 | D33: 71200 | E33: Gold loan | F33: Bullet | G33: 3 | H33: =IF(F33="Bullet",MIN(G33,Assumptions!$B$6),"") -> 2 | J33: =IF(F33="Monthly interest",MAX(0,Assumptions!$B$5-I33),"") | K33: =IF(F33="Bullet",G33*AD33,MAX(I33,1)*AD33) -> 2847 | L33: 46191 | M33: Medium | N33: Voice bot | O33: Early-stage delinquency: matched to risk and ticket size | P33: Call center | Q33: E - Other early delinquent | R33: Reminder + payment link | S33: Kannada | T33: Y | U33: Afternoon (12-4pm) | V33: Karnataka | W33: Bengaluru | X33: Bengaluru - Civil Lines | Y33: GL6684780985 | Z33: 46191 | AA33: 3 | AB33: =EDATE(Z33,AA33) -> 46283 | AC33: 16 | AD33: =ROUND(D33*AC33/100/12,0) -> 949 | AE33: =IF(F33="Bullet",H33*AD33,MIN(MAX(I33,1),Assumptions!$B$6)*AD33) -> 1898 | AF33: =IF(F33="Bullet",MAX(0,Assumptions!$B$4-AB33),MAX(0,Assumptions!$B$4-L33)) -> 15 | AH33: =IF(AG33="","",Assumptions!$B$4-AG33) | AI33: NA | AK33: 2 | AL33: 751 | AM33: 1 | AN33: N | AO33: 63.3 | AP33: 31 | AQ33: 46273 | AR33: Call center | AS33: Not reachable
A34: MFLC1000033 | B34: Venkatesh Setty | C34: 8053611000 | D34: 36700 | E34: Gold loan | F34: Monthly interest | H34: =IF(F34="Bullet",MIN(G34,Assumptions!$B$6),"") | I34: 2 | J34: =IF(F34="Monthly interest",MAX(0,Assumptions!$B$5-I34),"") -> 1 | K34: =IF(F34="Bullet",G34*AD34,MAX(I34,1)*AD34) -> 1346 | L34: 46255 | M34: Medium | N34: Voice bot | O34: Small ticket: bot-only, human cost not justified | P34: None - bot retry cadence | Q34: B - Small-ticket | R34: Standard reminder (no human follow-up) | S34: Telugu | T34: Y | U34: Morning (9am-12pm) | V34: Telangana | W34: Hyderabad | X34: Hyderabad - Church Road | Y34: GL3169938950 | Z34: 46043 | AA34: 12 | AB34: =EDATE(Z34,AA34) -> 46408 | AC34: 22 | AD34: =ROUND(D34*AC34/100/12,0) -> 673 | AE34: =IF(F34="Bullet",H34*AD34,MIN(MAX(I34,1),Assumptions!$B$6)*AD34) -> 1346 | AF34: =IF(F34="Bullet",MAX(0,Assumptions!$B$4-AB34),MAX(0,Assumptions!$B$4-L34)) -> 43 | AG34: 46226 | AH34: =IF(AG34="","",Assumptions!$B$4-AG34) -> 72 | AI34: Y | AJ34: 3 | AK34: 0 | AL34: 776 | AM34: 2 | AN34: N | AO34: 70.2 | AP34: 35 | AQ34: 46281 | AR34: Call center | AS34: Promised to pay
A35: MFLC1000034 | B35: Fathima Varghese | C35: 7809424699 | D35: 67800 | E35: Gold loan | F35: Bullet | G35: 3 | H35: =IF(F35="Bullet",MIN(G35,Assumptions!$B$6),"") -> 2 | J35: =IF(F35="Monthly interest",MAX(0,Assumptions!$B$5-I35),"") | K35: =IF(F35="Bullet",G35*AD35,MAX(I35,1)*AD35) -> 3051 | L35: 46199 | M35: Low | N35: Call center | O35: Escalated: not reachable on voice bot | P35: Field visit | Q35: E - Other early delinquent | R35: Reminder + payment link | S35: Malayalam | T35: Y | U35: Morning (9am-12pm) | V35: Kerala | W35: Kollam | X35: Kollam - Market Road | Y35: GL6920690877 | Z35: 46199 | AA35: 12 | AB35: =EDATE(Z35,AA35) -> 46564 | AC35: 18 | AD35: =ROUND(D35*AC35/100/12,0) -> 1017 | AE35: =IF(F35="Bullet",H35*AD35,MIN(MAX(I35,1),Assumptions!$B$6)*AD35) -> 2034 | AF35: =IF(F35="Bullet",MAX(0,Assumptions!$B$4-AB35),MAX(0,Assumptions!$B$4-L35)) -> 0 | AH35: =IF(AG35="","",Assumptions!$B$4-AG35) | AI35: NA | AK35: 0 | AL35: 623 | AM35: 1 | AN35: N | AO35: 74.8 | AP35: 30 | AQ35: 46296 | AR35: Voice bot | AS35: Not reachable
A36: MFLC1000035 | B36: Faisal Panicker | C36: 7276352551 | D36: 497100 | E36: Gold loan | F36: Bullet | G36: 3 | H36: =IF(F36="Bullet",MIN(G36,Assumptions!$B$6),"") -> 2 | J36: =IF(F36="Monthly interest",MAX(0,Assumptions!$B$5-I36),"") | K36: =IF(F36="Bullet",G36*AD36,MAX(I36,1)*AD36) -> 14913 | L36: 46184 | M36: Low | N36: Voice bot | O36: Early-stage delinquency: matched to risk and ticket size | P36: WhatsApp reminder | Q36: E - Other early delinquent | R36: Reminder + payment link | S36: Malayalam | T36: Y | U36: Evening (4-8pm) | V36: Kerala | W36: Kozhikode | X36: Kozhikode - Temple Street | Y36: GL1841547189 | Z36: 46184 | AA36: 12 | AB36: =EDATE(Z36,AA36) -> 46549 | AC36: 12 | AD36: =ROUND(D36*AC36/100/12,0) -> 4971 | AE36: =IF(F36="Bullet",H36*AD36,MIN(MAX(I36,1),Assumptions!$B$6)*AD36) -> 9942 | AF36: =IF(F36="Bullet",MAX(0,Assumptions!$B$4-AB36),MAX(0,Assumptions!$B$4-L36)) -> 0 | AH36: =IF(AG36="","",Assumptions!$B$4-AG36) | AI36: NA | AK36: 1 | AL36: 700 | AM36: 1 | AN36: N | AO36: 80.2 | AP36: 30 | AQ36: 46295 | AR36: WhatsApp reminder | AS36: Not reachable
A37: MFLC1000036 | B37: Saranya Sundaram | C37: 8183376000 | D37: 75700 | E37: Gold loan | F37: Bullet | G37: 4 | H37: =IF(F37="Bullet",MIN(G37,Assumptions!$B$6),"") -> 2 | J37: =IF(F37="Monthly interest",MAX(0,Assumptions!$B$5-I37),"") | K37: =IF(F37="Bullet",G37*AD37,MAX(I37,1)*AD37) -> 3532 | L37: 46169 | M37: Low | N37: Voice bot | O37: Early-stage delinquency: matched to risk and ticket size | P37: WhatsApp reminder | Q37: E - Other early delinquent | R37: Reminder + payment link | S37: Tamil | T37: Y | U37: Evening (4-8pm) | V37: Tamil Nadu | W37: Coimbatore | X37: Coimbatore - Gandhi Nagar | Y37: GL1443957122 | Z37: 46169 | AA37: 12 | AB37: =EDATE(Z37,AA37) -> 46534 | AC37: 14 | AD37: =ROUND(D37*AC37/100/12,0) -> 883 | AE37: =IF(F37="Bullet",H37*AD37,MIN(MAX(I37,1),Assumptions!$B$6)*AD37) -> 1766 | AF37: =IF(F37="Bullet",MAX(0,Assumptions!$B$4-AB37),MAX(0,Assumptions!$B$4-L37)) -> 0 | AH37: =IF(AG37="","",Assumptions!$B$4-AG37) | AI37: NA | AK37: 1 | AL37: 703 | AM37: 1 | AN37: N | AO37: 75.4 | AP37: 28 | AQ37: 46279 | AR37: Call center | AS37: No response
A38: MFLC1000037 | B38: Rakesh Rathore | C38: 9996999531 | D38: 90900 | E38: Gold loan | F38: Bullet | G38: 1 | H38: =IF(F38="Bullet",MIN(G38,Assumptions!$B$6),"") -> 1 | J38: =IF(F38="Monthly interest",MAX(0,Assumptions!$B$5-I38),"") | K38: =IF(F38="Bullet",G38*AD38,MAX(I38,1)*AD38) -> 985 | L38: 46253 | M38: Low | N38: WhatsApp reminder | O38: Early-stage delinquency: matched to risk and ticket size | P38: Voice bot | Q38: E - Other early delinquent | R38: Reminder + payment link | S38: Hindi | T38: Y | U38: Evening (4-8pm) | V38: Delhi | W38: Rohini | X38: Rohini - Town Hall | Y38: GL1696318091 | Z38: 46253 | AA38: 12 | AB38: =EDATE(Z38,AA38) -> 46618 | AC38: 13 | AD38: =ROUND(D38*AC38/100/12,0) -> 985 | AE38: =IF(F38="Bullet",H38*AD38,MIN(MAX(I38,1),Assumptions!$B$6)*AD38) -> 985 | AF38: =IF(F38="Bullet",MAX(0,Assumptions!$B$4-AB38),MAX(0,Assumptions!$B$4-L38)) -> 0 | AH38: =IF(AG38="","",Assumptions!$B$4-AG38) | AI38: NA | AK38: 0 | AL38: 650 | AM38: 0 | AN38: N | AO38: 72.9 | AP38: 17 | AQ38: 46276 | AR38: Call center | AS38: No response
A39: MFLC1000038 | B39: Ramesh Yadav | C39: 9755530823 | D39: 145200 | E39: Gold loan | F39: Monthly interest | H39: =IF(F39="Bullet",MIN(G39,Assumptions!$B$6),"") | I39: 1 | J39: =IF(F39="Monthly interest",MAX(0,Assumptions!$B$5-I39),"") -> 2 | K39: =IF(F39="Bullet",G39*AD39,MAX(I39,1)*AD39) -> 1815 | L39: 46274 | M39: Low | N39: WhatsApp reminder | O39: Slipped regular payer: gentle digital nudge | P39: Voice bot | Q39: A - Regular monthly payer | R39: Gentle reminder + eNACH nudge | S39: Hindi | T39: Y | U39: Morning (9am-12pm) | V39: Madhya Pradesh | W39: Indore | X39: Indore - Temple Street | Y39: GL2604364267 | Z39: 46031 | AA39: 12 | AB39: =EDATE(Z39,AA39) -> 46396 | AC39: 15 | AD39: =ROUND(D39*AC39/100/12,0) -> 1815 | AE39: =IF(F39="Bullet",H39*AD39,MIN(MAX(I39,1),Assumptions!$B$6)*AD39) -> 1815 | AF39: =IF(F39="Bullet",MAX(0,Assumptions!$B$4-AB39),MAX(0,Assumptions!$B$4-L39)) -> 24 | AG39: 46244 | AH39: =IF(AG39="","",Assumptions!$B$4-AG39) -> 54 | AI39: Y | AJ39: 1 | AK39: 0 | AL39: 852 | AM39: 0 | AN39: N | AO39: 68.6 | AP39: 5 | AQ39: 46287 | AR39: WhatsApp reminder | AS39: Promised to pay
A40: MFLC1000039 | B40: Remya Warrier | C40: 9992563338 | D40: 82400 | E40: Gold loan | F40: Bullet | G40: 3 | H40: =IF(F40="Bullet",MIN(G40,Assumptions!$B$6),"") -> 2 | J40: =IF(F40="Monthly interest",MAX(0,Assumptions!$B$5-I40),"") | K40: =IF(F40="Bullet",G40*AD40,MAX(I40,1)*AD40) -> 3708 | L40: 46182 | M40: Low | N40: Voice bot | O40: Early-stage delinquency: matched to risk and ticket size | P40: WhatsApp reminder | Q40: E - Other early delinquent | R40: Reminder + payment link | S40: Malayalam | T40: Y | U40: Evening (4-8pm) | V40: Kerala | W40: Alappuzha | X40: Alappuzha - Temple Street | Y40: GL0657724044 | Z40: 46182 | AA40: 6 | AB40: =EDATE(Z40,AA40) -> 46365 | AC40: 18 | AD40: =ROUND(D40*AC40/100/12,0) -> 1236 | AE40: =IF(F40="Bullet",H40*AD40,MIN(MAX(I40,1),Assumptions!$B$6)*AD40) -> 2472 | AF40: =IF(F40="Bullet",MAX(0,Assumptions!$B$4-AB40),MAX(0,Assumptions!$B$4-L40)) -> 0 | AH40: =IF(AG40="","",Assumptions!$B$4-AG40) | AI40: NA | AK40: 1 | AL40: 729 | AM40: 0 | AN40: N | AO40: 73.9 | AP40: 14 | AS40: No prior contact
...

Sheet Summary
A1: Summary of sample collections pool (2,000 gold loan customers)
A2: All figures are live COUNTIFS/SUMIFS on the Customers sheet.
A4: By payment scheme
A5: Payment scheme | B5: Customers | C5: % of total | D5: Total POS (₹) | E5: Total due (₹)
A6: Bullet | B6: =COUNTIF(Customers!$F$2:$F$2001,A6) -> 874 | C6: =B6/COUNTA(Customers!$A$2:$A$2001) -> 0.437 | D6: =SUMIFS(Customers!$D$2:$D$2001,Customers!$F$2:$F$2001,A6) -> 158403400 | E6: =SUMIFS(Customers!$K$2:$K$2001,Customers!$F$2:$F$2001,A6) -> 6450692
A7: Monthly interest | B7: =COUNTIF(Customers!$F$2:$F$2001,A7) -> 1126 | C7: =B7/COUNTA(Customers!$A$2:$A$2001) -> 0.563 | D7: =SUMIFS(Customers!$D$2:$D$2001,Customers!$F$2:$F$2001,A7) -> 205733600 | E7: =SUMIFS(Customers!$K$2:$K$2001,Customers!$F$2:$F$2001,A7) -> 4560693
A8: Total | B8: =SUM(B6:B7) -> 2000 | C8: =SUM(C6:C7) -> 1 | D8: =SUM(D6:D7) -> 364137000 | E8: =SUM(E6:E7) -> 11011385
A10: By risk tier
A11: Risk tier | B11: Customers | C11: % of total | D11: Total POS (₹) | E11: Total due (₹)
A12: High | B12: =COUNTIF(Customers!$M$2:$M$2001,A12) -> 519 | C12: =B12/COUNTA(Customers!$A$2:$A$2001) -> 0.2595 | D12: =SUMIFS(Customers!$D$2:$D$2001,Customers!$M$2:$M$2001,A12) -> 97141200 | E12: =SUMIFS(Customers!$K$2:$K$2001,Customers!$M$2:$M$2001,A12) -> 4057076
A13: Medium | B13: =COUNTIF(Customers!$M$2:$M$2001,A13) -> 688 | C13: =B13/COUNTA(Customers!$A$2:$A$2001) -> 0.344 | D13: =SUMIFS(Customers!$D$2:$D$2001,Customers!$M$2:$M$2001,A13) -> 124490900 | E13: =SUMIFS(Customers!$K$2:$K$2001,Customers!$M$2:$M$2001,A13) -> 3843687
A14: Low | B14: =COUNTIF(Customers!$M$2:$M$2001,A14) -> 793 | C14: =B14/COUNTA(Customers!$A$2:$A$2001) -> 0.3965 | D14: =SUMIFS(Customers!$D$2:$D$2001,Customers!$M$2:$M$2001,A14) -> 142504900 | E14: =SUMIFS(Customers!$K$2:$K$2001,Customers!$M$2:$M$2001,A14) -> 3110622
A16: By suggested channel
A17: Suggested channel | B17: Customers | C17: % of total | D17: Total POS (₹) | E17: Total due (₹)
A18: WhatsApp reminder | B18: =COUNTIF(Customers!$N$2:$N$2001,A18) -> 509 | C18: =B18/COUNTA(Customers!$A$2:$A$2001) -> 0.2545 | D18: =SUMIFS(Customers!$D$2:$D$2001,Customers!$N$2:$N$2001,A18) -> 91034300 | E18: =SUMIFS(Customers!$K$2:$K$2001,Customers!$N$2:$N$2001,A18) -> 1564057
A19: Voice bot | B19: =COUNTIF(Customers!$N$2:$N$2001,A19) -> 772 | C19: =B19/COUNTA(Customers!$A$2:$A$2001) -> 0.386 | D19: =SUMIFS(Customers!$D$2:$D$2001,Customers!$N$2:$N$2001,A19) -> 119872900 | E19: =SUMIFS(Customers!$K$2:$K$2001,Customers!$N$2:$N$2001,A19) -> 3378410
A20: Bot + call center | B20: =COUNTIF(Customers!$N$2:$N$2001,A20) -> 519 | C20: =B20/COUNTA(Customers!$A$2:$A$2001) -> 0.2595 | D20: =SUMIFS(Customers!$D$2:$D$2001,Customers!$N$2:$N$2001,A20) -> 97141200 | E20: =SUMIFS(Customers!$K$2:$K$2001,Customers!$N$2:$N$2001,A20) -> 4057076
A21: Call center | B21: =COUNTIF(Customers!$N$2:$N$2001,A21) -> 200 | C21: =B21/COUNTA(Customers!$A$2:$A$2001) -> 0.1 | D21: =SUMIFS(Customers!$D$2:$D$2001,Customers!$N$2:$N$2001,A21) -> 56088600 | E21: =SUMIFS(Customers!$K$2:$K$2001,Customers!$N$2:$N$2001,A21) -> 2011842
A23: Treatment segment x suggested channel (customers)
A24: Treatment segment | B24: WhatsApp reminder | C24: Voice bot | D24: Bot + call center | E24: Call center | F24: Total
A25: A - Regular monthly payer | B25: =COUNTIFS(Customers!$Q$2:$Q$2001,$A25,Customers!$N$2:$N$2001,B$24) -> 309 | C25: =COUNTIFS(Customers!$Q$2:$Q$2001,$A25,Customers!$N$2:$N$2001,C$24) -> 215 | D25: =COUNTIFS(Customers!$Q$2:$Q$2001,$A25,Customers!$N$2:$N$2001,D$24) -> 0 | E25: =COUNTIFS(Customers!$Q$2:$Q$2001,$A25,Customers!$N$2:$N$2001,E$24) -> 0 | F25: =SUM(B25:E25) -> 524
A26: B - Small-ticket | B26: =COUNTIFS(Customers!$Q$2:$Q$2001,$A26,Customers!$N$2:$N$2001,B$24) -> 62 | C26: =COUNTIFS(Customers!$Q$2:$Q$2001,$A26,Customers!$N$2:$N$2001,C$24) -> 161 | D26: =COUNTIFS(Customers!$Q$2:$Q$2001,$A26,Customers!$N$2:$N$2001,D$24) -> 53 | E26: =COUNTIFS(Customers!$Q$2:$Q$2001,$A26,Customers!$N$2:$N$2001,E$24) -> 0 | F26: =SUM(B26:E26) -> 276
A27: C - Accrued bullet | B27: =COUNTIFS(Customers!$Q$2:$Q$2001,$A27,Customers!$N$2:$N$2001,B$24) -> 0 | C27: =COUNTIFS(Customers!$Q$2:$Q$2001,$A27,Customers!$N$2:$N$2001,C$24) -> 53 | D27: =COUNTIFS(Customers!$Q$2:$Q$2001,$A27,Customers!$N$2:$N$2001,D$24) -> 167 | E27: =COUNTIFS(Customers!$Q$2:$Q$2001,$A27,Customers!$N$2:$N$2001,E$24) -> 11 | F27: =SUM(B27:E27) -> 231
A28: D - Bouncing EII | B28: =COUNTIFS(Customers!$Q$2:$Q$2001,$A28,Customers!$N$2:$N$2001,B$24) -> 0 | C28: =COUNTIFS(Customers!$Q$2:$Q$2001,$A28,Customers!$N$2:$N$2001,C$24) -> 0 | D28: =COUNTIFS(Customers!$Q$2:$Q$2001,$A28,Customers!$N$2:$N$2001,D$24) -> 244 | E28: =COUNTIFS(Customers!$Q$2:$Q$2001,$A28,Customers!$N$2:$N$2001,E$24) -> 0 | F28: =SUM(B28:E28) -> 244
A29: E - Other early delinquent | B29: =COUNTIFS(Customers!$Q$2:$Q$2001,$A29,Customers!$N$2:$N$2001,B$24) -> 138 | C29: =COUNTIFS(Customers!$Q$2:$Q$2001,$A29,Customers!$N$2:$N$2001,C$24) -> 343 | D29: =COUNTIFS(Customers!$Q$2:$Q$2001,$A29,Customers!$N$2:$N$2001,D$24) -> 55 | E29: =COUNTIFS(Customers!$Q$2:$Q$2001,$A29,Customers!$N$2:$N$2001,E$24) -> 189 | F29: =SUM(B29:E29) -> 725
A30: Total | B30: =SUM(B25:B29) -> 509 | C30: =SUM(C25:C29) -> 772 | D30: =SUM(D25:D29) -> 519 | E30: =SUM(E25:E29) -> 200 | F30: =SUM(F25:F29) -> 2000
A32: Monthly-interest customers by months unpaid (NPA at 3 months)
A33: Months unpaid | B33: Months to NPA | C33: Customers | D33: % of monthly-interest customers
A34: 1 | B34: =Assumptions!$B$5-A34 -> 2 | C34: =COUNTIF(Customers!$I$2:$I$2001,A34) -> 638 | D34: =C34/SUM($C$34:$C$35) -> 0.56660746
A35: 2 | B35: =Assumptions!$B$5-A35 -> 1 | C35: =COUNTIF(Customers!$I$2:$I$2001,A35) -> 488 | D35: =C35/SUM($C$34:$C$35) -> 0.43339254
A36: eNACH registered (monthly-interest) | C36: =COUNTIFS(Customers!$F$2:$F$2001,"Monthly interest",Customers!$AI$2:$AI$2001,"Y") -> 344 | D36: =C36/SUM($C$34:$C$35) -> 0.30550622
A38: By fallback channel
A39: Fallback channel | B39: Customers | C39: % of total
A40: Voice bot | B40: =COUNTIF(Customers!$P$2:$P$2001,A40) -> 509 | C40: =B40/COUNTA(Customers!$A$2:$A$2001) -> 0.2545
A41: WhatsApp reminder | B41: =COUNTIF(Customers!$P$2:$P$2001,A41) -> 178 | C41: =B41/COUNTA(Customers!$A$2:$A$2001) -> 0.089
A42: Call center | B42: =COUNTIF(Customers!$P$2:$P$2001,A42) -> 433 | C42: =B42/COUNTA(Customers!$A$2:$A$2001) -> 0.2165
A43: Field visit | B43: =COUNTIF(Customers!$P$2:$P$2001,A43) -> 719 | C43: =B43/COUNTA(Customers!$A$2:$A$2001) -> 0.3595
A44: None - bot retry cadence | B44: =COUNTIF(Customers!$P$2:$P$2001,A44) -> 161 | C44: =B44/COUNTA(Customers!$A$2:$A$2001) -> 0.0805
A47: By preferred language (voice bot / WhatsApp)
A48: Language | B48: Customers | C48: % of total
...

Sheet Assumptions
A1: Assumptions, rules and notes
A2: Yellow cells B4:B6 are live inputs used by formulas on the Customers sheet. B7:B10 are documented cut-offs that were applied when the static columns (risk tier, segment, channel) were built; changing them does not recalculate those columns.
A3: Parameter | B3: Value | C3: Used by / note
A4: As-of date | B4: 46298 | C4: Reference date for days past due and days since last payment. Assumption: today's date.
A5: NPA trigger (months of unpaid interest) | B5: 3 | C5: Per your input: if interest is unpaid for 3 months the account turns NPA. Drives "Monthly: months to NPA" = trigger - months unpaid. Every monthly-interest account in the sample has 1-2 months unpaid, so months to NPA is always 1 or 2. Static risk tier/channel columns do NOT recalc if this changes.
A6: Max months of interest the bot asks for (minimum amount due) | B6: 2 | C6: Drives "Bullet: months bot should try to collect" and "Bot ask amount". Based on your example of securing 2 months of pending interest.
A7: Small-ticket POS threshold (₹) | B7: 50000 | C7: Used to assign segment B and to size the channel (documented; values on Customers are static).
A8: Large-ticket POS threshold (₹) | B8: 200000 | C8: Used in channel logic for large-ticket customers (documented; values on Customers are static).
A9: Risk tier cut-off: Medium from score | B9: 31 | C9: Score below this = Low. Cut-offs set so roughly 40% Low / 34% Medium / 26% High.
A10: Risk tier cut-off: High from score | B10: 48 | C10: Score at or above this = High.
A13: Treatment segments (rule order: first match wins)
A14: C - Accrued bullet | B14: Bullet scheme with 5-6 months of interest accrued | C14: Bot negotiates a minimum amount due
A15: D - Bouncing EII | B15: Monthly-interest, POS >= ₹50k and risk = High | C15: Bot + call center
A16: B - Small-ticket | B16: POS < ₹50k (not already C) | C16: Bot/digital reminders; call center added only if risk = High
A17: A - Regular monthly payer | B17: Monthly-interest, POS >= ₹50k, 1 month unpaid (just slipped), risk not High | C17: WhatsApp nudge; push eNACH
A18: E - Other early delinquent | B18: Everything else (ADDED by me; you defined A-D only) | C18: Matched to risk tier and ticket size
A20: Suggested channel logic (base rule, then response-based reallocation, then consent check)
A21: RULE 1 - High risk | B21: Every High-risk customer is "Bot + call center": the voice bot goes first and the call center follows up (non-responders, negotiation, promise-to-pay). Applies to all segments.
A22: A | B22: WhatsApp reminder
A23: B (not High risk) | B23: WhatsApp reminder if 1 month unpaid, else Voice bot
A24: C (not High risk) | B24: Voice bot negotiates the minimum amount due
A25: E (not High risk) | B25: Low risk: WhatsApp reminder (Voice bot if 3+ months of bullet interest) | Medium risk: Voice bot; Call center if POS > ₹2L and urgent (monthly with 2 months unpaid, or bullet with 3+ months)
A26: Reallocation on response | B26: Non-High-risk customers: if the last attempt used the same channel and got No response / Not reachable, move one rung up (WhatsApp > Voice bot > Call center), capped per segment (A, B: Voice bot; C, E: Call center). Refused / disputed goes to Call center (not A, B).
A27: Consent check | B27: If WhatsApp is the suggested channel but WhatsApp opt-in = N, route to Voice bot.
A28: Fallback channel | B28: WhatsApp > Voice bot | Voice bot > WhatsApp (Low risk with opt-in), None for segment B, else Call center | Call center and Bot + call center > Field visit
A29: Field visit | B29: No longer a first-line channel. It is the fallback after Bot + call center / Call center. Tell me if you want it back as a first-line channel for the highest-urgency accounts.
A31: How the sample data was generated (all values are synthetic)
A32: Mobile numbers / names | B32: Randomly generated and fictitious. Random 10-digit numbers could belong to real people: replace with test numbers before any live voice-bot or WhatsApp trial.
A33: Payment scheme mix | B33: ~56% Monthly interest, ~44% Bullet. Bullet tenures: 3M 12%, 6M 58%, 12M 30% (6M largest, as in the Bullet 3M/6M/12M cut on your collections page).
A34: Months unpaid (monthly) | B34: 1 month: ~57%, 2 months: ~43%. Accounts with 0 months unpaid (not yet due) are excluded, so every monthly-interest account is within 1-2 months of NPA (3-month trigger). This is the at-risk collections pool, consistent with your "20-40% of EII loans at risk of NPA in 3 months".
A35: eNACH | B35: ~30% of monthly-interest loans have eNACH, i.e. ~70% do not (your 60-80% without NACH).
A36: POS | B36: Log-normal, median ~₹1.2L, range ₹15k to ₹25L.
A37: Interest rate | B37: Bullet 12-18% p.a.; Monthly interest 14-24% p.a. (illustrative, not Muthoot's rate card).
A38: Risk score | B38: Weighted on-us behaviour (months unpaid, missed payments, broken promises; for bullets, accrual months and maturity pressure), off-us signals (bureau score, off-us loans, off-us delinquency) and LTV, plus noise. Scaled 0-100. Bullets are not subject to the 3-month NPA clock (bullet NPA depends on maturity), so their months of interest due can run to 6.
A39: Static vs formula columns | B39: Green headers on Customers are live formulas (due amount, months to NPA, bot ask, days past due, maturity). Risk score, risk tier, segment, channel and fallback are static model-style outputs.

Sheet Data dictionary
A1: Data dictionary
A2: Navy headers = columns you asked for. Blue = columns I added. Teal = live formula columns.
A4: # | B4: Column | C4: Requested / Added | D4: Type | E4: Description
A5: 1 | B5: Customer ID | C5: Requested | D5: Data | E5: Unique customer identifier (synthetic).
A6: 2 | B6: Customer name | C6: Requested | D6: Data | E6: Customer name (synthetic, matched to state/language).
A7: 3 | B7: Mobile no. | C7: Requested | D7: Data | E7: 10-digit mobile number (synthetic). Do not dial.
A8: 4 | B8: POS (₹) | C8: Requested | D8: Data | E8: Principal outstanding on the gold loan, in ₹.
A9: 5 | B9: Loan type | C9: Requested | D9: Data | E9: Loan type. All rows are Gold loan.
A10: 6 | B10: Payment scheme | C10: Requested | D10: Data | E10: Bullet (interest + principal at maturity) or Monthly interest (EII).
A11: 7 | B11: Bullet: months of interest due | C11: Requested | D11: Data | E11: Bullet only: months of interest accrued and unpaid.
A12: 8 | B12: Bullet: months bot should try to collect | C12: Requested | D12: Formula | E12: Bullet only: months of interest the bot tries to collect = MIN(months due, max months on Assumptions).
A13: 9 | B13: Monthly: months of interest unpaid | C13: Requested | D13: Data | E13: Monthly-interest only: months of interest not paid.
A14: 10 | B14: Monthly: months to NPA | C14: Requested | D14: Formula | E14: Monthly-interest only: months left before NPA = NPA trigger (3 months) - months unpaid, so always 1 or 2 in this sample.
A15: 11 | B15: Due amount (₹) | C15: Requested | D15: Formula | E15: Months of interest due x monthly interest. For monthly customers who are current (0 months unpaid), shows the upcoming month's interest.
A16: 12 | B16: Due since | C16: Requested | D16: Data | E16: Monthly: date of the oldest unpaid due date (or the upcoming due date if current). Bullet: date interest started accruing (loan start).
... A49: 45 | B49: Last contact outcome | C49: Added | D49: Data | E49: Outcome of the most recent contact.
